Workbook

Sheet 1_20251104.wos
A1: Publication Type | B1: Authors | C1: Book Authors | D1: Book Editors | E1: Book Group Authors | F1: Author Full Names | G1: Book Author Full Names | H1: Group Authors | I1: Article Title | J1: Source Title | K1: Book Series Title | L1: Book Series Subtitle | M1: Language | N1: Document Type | O1: Conference Title | P1: Conference Date | Q1: Conference Location | R1: Conference Sponsor | S1: Conference Host | T1: Author Keywords | U1: Keywords Plus | V1: Abstract | W1: Addresses | X1: Affiliations | Y1: Reprint Addresses | Z1: Email Addresses | AA1: Researcher Ids | AB1: ORCIDs | AC1: Funding Orgs | AD1: Funding Name Preferred | AE1: Funding Text | AF1: Cited References | AG1: Cited Reference Count | AH1: Times Cited, WoS Core | AI1: Times Cited, All Databases | AJ1: 180 Day Usage Count | AK1: Since 2013 Usage Count | AL1: Publisher | AM1: Publisher City | AN1: Publisher Address | AO1: ISSN | AP1: eISSN | AQ1: ISBN | AR1: Journal Abbreviation | AS1: Journal ISO Abbreviation | AT1: Publication Date | AU1: Publication Year | AV1: Volume | AW1: Issue | AX1: Part Number | AY1: Supplement | AZ1: Special Issue | BA1: Meeting Abstract | BB1: Start Page | BC1: End Page | BD1: Article Number | BE1: DOI | BF1: DOI Link | BG1: Book DOI | BH1: Early Access Date | BI1: Number of Pages | BJ1: WoS Categories | BK1: Web of Science Index | BL1: Research Areas | BM1: IDS Number | BN1: Pubmed Id | BO1: Open Access Designations | BP1: Highly Cited Status | BQ1: Hot Paper Status | BR1: Date of Export | BS1: UT (Unique WOS ID) | BT1: Web of Science Record
A2: J | B2: Jones, D; Snider, C; Nassehi, A; Yon, J; Hicks, B | F2: Jones, David; Snider, Chris; Nassehi, Aydin; Yon, Jason; Hicks, Ben | I2: Characterising the Digital Twin: A systematic literature review | J2: CIRP JOURNAL OF MANUFACTURING SCIENCE AND TECHNOLOGY | M2: English | N2: Review | T2: Digital Twin; Virtual Twin | U2: MODEL-PREDICTIVE CONTROL; SERVICE; DESIGN; FUTURE; METHODOLOGY; INFORMATION; ENVIRONMENT; AUTOMATION; SIMULATION | V2: While there has been a recent growth of interest in the Digital Twin, a variety of definitions employed across industry and academia remain. There is a need to consolidate research such to maintain a common understanding of the topic and ensure future research efforts are to be based on solid foundations. Through a systematic literature review and a thematic analysis of 92 Digital Twin publications from the last ten years, this paper provides a characterisation of the Digital Twin, identification of gaps in knowledge, and required areas of future research. In characterising the Digital Twin, the state of the concept, key terminology, and associated processes are identified, discussed, and consolidated to produce 13 characteristics (Physical Entity/Twin; Virtual Entity/Twin; Physical Environment; Virtual Environment; State; Realisation; Metrology; Twinning; Twinning Rate; Physical-to-Virtual Connection/Twinning; Virtual-to-Physical Connection/Twinning; Physical Processes; and Virtual Processes) and a complete framework of the Digital Twin and its process of operation. Following this characterisation, seven knowledge gaps and topics for future research focus are identified: Perceived Benefits; Digital Twin across the Product Life-Cycle; Use-Cases; Technical Implementations; Levels of Fidelity; Data Ownership; and Integration between Virtual Entities; each of which are required to realise the Digital Twin. (C) 2020 University of Bristol. | W2: [Jones, David; Snider, Chris; Nassehi, Aydin; Yon, Jason; Hicks, Ben] Univ Bristol, Dept Mech Engn, Queens Bldg, Bristol BS8 1TR, Avon, England | X2: University of Bristol | Y2: Jones, D (corresponding author), Univ Bristol, Dept Mech Engn, Queens Bldg, Bristol BS8 1TR, Avon, England. | Z2: david.jones@bristol.ac.uk; chris.snider@bristol.ac.uk; aydin.nassehi@bristol.ac.uk; jason.yon.02@bristol.ac.uk; ben.hicks@bristol.ac.uk | AA2: ; Hicks, Ben/A-9185-2010; Snider, Chris/AAR-6791-2020; Nassehi, Aydin/C-6810-2008 | AB2: Hicks, Ben/0000-0001-8294-4694; Snider, Chris/0000-0003-2692-110X; Yon, Jason/0000-0002-9384-4311; Nassehi, Aydin/0000-0003-3417-3391; Jones, David/0000-0002-6209-2698 | AC2: Engineering and Physical Sciences Research Council (EPSRC) [EP/R032696/1]; EPSRC [EP/R032696/1] Funding Source: UKRI | AD2: Engineering and Physical Sciences Research Council (EPSRC)(UK Research & Innovation (UKRI)Engineering & Physical Sciences Research Council (EPSRC)); EPSRC(UK Research & Innovation (UKRI)Engineering & Physical Sciences Research Council (EPSRC)) | AE2: The work reported in this paper has been undertaken as part of the project: Improving the product development process through integrated revision control and twinning of digital-physical models during prototyping. The work was conducted at the University of Bristol in the Design and Manufacturing Futures Lab (http://www.dmf-lab.co.uk) and is funded by the Engineering and Physical Sciences Research Council (EPSRC), Grant reference EP/R032696/1. | AG2: 112 | AH2: 1249 | AI2: 1442 | AJ2: 114 | AK2: 2197 | AL2: ELSEVIER | AM2: AMSTERDAM | AN2: RADARWEG 29, 1043 NX AMSTERDAM, NETHERLANDS | AO2: 1755-5817 | AP2: 1878-0016 | AR2: CIRP J MANUF SCI TEC | AS2: CIRP J. Manuf. Sci. Technol. | AT2: MAY | AU2: 2020 | AV2: 29 | AX2: A | BB2: 36 | BC2: 52 | BE2: 10.1016/j.cirpj.2020.02.002 | BF2: =HYPERLINK("http://dx.doi.org/10.1016/j.cirpj.2020.02.002","http://dx.doi.org/10.1016/j.cirpj.2020.02.002") -> http://dx.doi.org/10.1016/j.cirpj.2020.02.002 | BI2: 17 | BJ2: Engineering, Manufacturing | BK2: Science Citation Index Expanded (SCI-EXPANDED) | BL2: Engineering | BM2: LY2HI | BO2: Green Submitted, hybrid | BP2: Y | BQ2: N | BR2: 2025-11-04 | BS2: WOS:000540340800004 | BT2: =HYPERLINK("https%3A%2F%2Fwww.webofscience.com%2Fwos%2Fwoscc%2Ffull-record%2FWOS:000540340800004","View Full Record in Web of Science") -> View Full Record in Web of Science
A3: J | B3: Semeraro, C; Lezoche, M; Panetto, H; Dassisti, M | F3: Semeraro, Concetta; Lezoche, Mario; Panetto, Herve; Dassisti, Michele | I3: Digital twin paradigm: A systematic literature review | J3: COMPUTERS IN INDUSTRY | M3: English | N3: Review | T3: Digital twin; Industry 4; 0; Cyber-physical systems; Predictive manufacturing | U3: CYBER-PHYSICAL SYSTEMS; INDUSTRY 4.0; BIG DATA; DATA-DRIVEN; MANUFACTURING SYSTEM; FAULT-DIAGNOSIS; THINGS IOT; DESIGN; FUTURE; MODEL | V3: Manufacturing enterprises are facing the need to align themselves to the new information technologies (IT) and respond to the new challenges of variable market demand. One of the key enablers of this IT revolution toward Smart Manufacturing is the digital twin (DT). It embeds a virtual image of the real-ity constantly synchronized with the real operating scenario to provide sound information (knowledge model) to reality interpretation model to draw sound decisions. The paper aims at providing an up-to date picture of the main DT components, their features and interaction problems. The paper aims at clearly tracing the ongoing research and technical challenges in conceiving and building DTs as well, according to different application domains and related technologies. To this purpose, the main questions answered here are: 'What is a Digital Twin?'; 'Where is appropriate to use a Digital Twin?'; 'When has a Digital Twin to be developed?'; 'Why should a Digital Twin be used?'; 'How to design and implement a Digital Twin?'; 'What are the main challenges of implementing a Digital Twin?'. This study tries to answer to the previous questions funding on a wide systematic literature review of scientific research, tools, and technicalities in different application domains. (c) 2021 Elsevier B.V. All rights reserved. | W3: [Semeraro, Concetta; Lezoche, Mario; Panetto, Herve] Univ Lorraine, CNRS, CRAN, Nancy, France; [Semeraro, Concetta; Dassisti, Michele] Polytech Univ Bari, Dept Mech Management & Math DMMM, Bari, Italy | X3: Centre National de la Recherche Scientifique (CNRS); Universite de Lorraine; Politecnico di Bari | Y3: Semeraro, C (corresponding author), Univ Lorraine, CNRS, CRAN, Nancy, France. | Z3: concetta.semeraro@univ-lorraine.fr; mario.lezoche@univ-lorraine.fr; herve.panetto@univ-lorraine.fr; michele.dassisti@poliba.it | AA3: Dassisti, Michele/I-2668-2012; semeraro, concetta/AHA-4914-2022; Panetto, Herve/B-4626-2010; Lezoche, Mario/M-9236-2018; Panetto, Hervé/B-4626-2010 | AB3: Panetto, Herve/0000-0002-5537-2261; SEMERARO, CONCETTA/0000-0001-5152-0004; | AC3: Italian Ministry of Education, University and Research under the Programme Department of Excellence Legge [232/2016, CUP-D94I18000260001] | AD3: Italian Ministry of Education, University and Research under the Programme Department of Excellence Legge | AE3: This work was supported by the Italian Ministry of Education, University and Research under the Programme Department of Excellence Legge 232/2016 (Grant No. CUP-D94I18000260001) | AG3: 155 | AH3: 499 | AI3: 571 | AJ3: 56 | AK3: 879 | AL3: ELSEVIER | AM3: AMSTERDAM | AN3: RADARWEG 29, 1043 NX AMSTERDAM, NETHERLANDS | AO3: 0166-3615 | AP3: 1872-6194 | AR3: COMPUT IND | AS3: Comput. Ind. | AT3: SEP | AU3: 2021 | AV3: 130 | BD3: 103469 | BE3: 10.1016/j.compind.2021.103469 | BF3: =HYPERLINK("http://dx.doi.org/10.1016/j.compind.2021.103469","http://dx.doi.org/10.1016/j.compind.2021.103469") -> http://dx.doi.org/10.1016/j.compind.2021.103469 | BH3: MAY 2021 | BI3: 23 | BJ3: Computer Science, Interdisciplinary Applications | BK3: Science Citation Index Expanded (SCI-EXPANDED) | BL3: Computer Science | BM3: SM3WX | BO3: Green Submitted | BP3: Y | BQ3: N | BR3: 2025-11-04 | BS3: WOS:000657540900006 | BT3: =HYPERLINK("https%3A%2F%2Fwww.webofscience.com%2Fwos%2Fwoscc%2Ffull-record%2FWOS:000657540900006","View Full Record in Web of Science") -> View Full Record in Web of Science
A4: J | B4: Rathore, MM; Shah, SA; Shukla, D; Bentafat, E; Bakiras, S | F4: Rathore, M. Mazhar; Shah, Syed Attique; Shukla, Dhirendra; Bentafat, Elmahdi; Bakiras, Spiridon | I4: The Role of AI, Machine Learning, and Big Data in Digital Twinning: A Systematic Literature Review, Challenges, and Opportunities | J4: IEEE ACCESS | M4: English | N4: Review | T4: Big Data; Digital twin; Patents; Industries; Systematics; Tools; Libraries; Digital twin; artificial intelligence; machine learning; big data; industry 40 | U4: HEALTH MANAGEMENT; FAULT-DIAGNOSIS; DATA ANALYTICS; FRAMEWORK; TWINS; ARCHITECTURE; PROGNOSTICS; NETWORKS; SERVICES; DESIGN | V4: Digital twinning is one of the top ten technology trends in the last couple of years, due to its high applicability in the industrial sector. The integration of big data analytics and artificial intelligence/machine learning (AI-ML) techniques with digital twinning, further enriches its significance and research potential with new opportunities and unique challenges. To date, a number of scientific models have been designed and implemented related to this evolving topic. However, there is no systematic review of digital twinning, particularly focusing on the role of AI-ML and big data, to guide the academia and industry towards future developments. Therefore, this article emphasizes the role of big data and AI-ML in the creation of digital twins (DTs) or DT-based systems for various industrial applications, by highlighting the current state-of-the-art deployments. We performed a systematic review on top of multidisciplinary electronic bibliographic databases, in addition to existing patents in the field. Also, we identified development-tools that can facilitate various levels of the digital twinning. Further, we designed a big data driven and AI-enriched reference architecture that leads developers to a complete DT-enabled system. Finally, we highlighted the research potential of AI-ML for digital twinning by unveiling challenges and current opportunities. | W4: [Rathore, M. Mazhar; Bentafat, Elmahdi; Bakiras, Spiridon] Hamad Bin Khalifa Univ, Div Informat & Comp Technol, Coll Sci & Engn, Doha, Qatar; [Shah, Syed Attique] Univ Tartu, Inst Comp Sci, Data Syst Grp, EE-51009 Tartu, Estonia; [Shukla, Dhirendra] Univ New Brunswick, Dr J Herbert Smith Ctr, Fredericton, NB E3B 5A3, Canada | X4: Qatar Foundation (QF); Hamad Bin Khalifa University-Qatar; University of Tartu; University of New Brunswick | Y4: Bakiras, S (corresponding author), Hamad Bin Khalifa Univ, Div Informat & Comp Technol, Coll Sci & Engn, Doha, Qatar. | Z4: sbakiras@hbku.edu.qa | AA4: ; Shah, Syed Attique/ABD-6564-2021 | AB4: Shukla, Dhirendra/0000-0002-0036-714X; Shah, Syed Attique/0000-0003-2949-7391; Bakiras, Spiridon/0000-0002-8964-0746; Rathore, Muhammad Mazhar/0000-0002-0701-9850 | AG4: 175 | AH4: 270 | AI4: 327 | AJ4: 66 | AK4: 588 | AL4: IEEE-INST ELECTRICAL ELECTRONICS ENGINEERS INC | AM4: PISCATAWAY | AN4: 445 HOES LANE, PISCATAWAY, NJ 08855-4141 USA | AO4: 2169-3536 | AR4: IEEE ACCESS | AS4: IEEE Access | AU4: 2021 | AV4: 9 | BB4: 32030 | BC4: 32052 | BE4: 10.1109/ACCESS.2021.3060863 | BF4: =HYPERLINK("http://dx.doi.org/10.1109/ACCESS.2021.3060863","http://dx.doi.org/10.1109/ACCESS.2021.3060863") -> http://dx.doi.org/10.1109/ACCESS.2021.3060863 | BI4: 23 | BJ4: Computer Science, Information Systems; Engineering, Electrical & Electronic; Telecommunications | BK4: Science Citation Index Expanded (SCI-EXPANDED); Social Science Citation Index (SSCI) | BL4: Computer Science; Engineering; Telecommunications | BM4: QO8UB | BO4: Green Submitted, gold | BP4: Y | BQ4: N | BR4: 2025-11-04 | BS4: WOS:000623411600001 | BT4: =HYPERLINK("https%3A%2F%2Fwww.webofscience.com%2Fwos%2Fwoscc%2Ffull-record%2FWOS:000623411600001","View Full Record in Web of Science") -> View Full Record in Web of Science
A5: J | B5: van Dinter, R; Tekinerdogan, B; Catal, C | F5: van Dinter, Raymon; Tekinerdogan, Bedir; Catal, Cagatay | I5: Predictive maintenance using digital twins: A systematic literature review | J5: INFORMATION AND SOFTWARE TECHNOLOGY | M5: English | N5: Review | T5: Systematic literature review; Active learning; Digital twin; Predictive maintenance | U5: HEALTH MANAGEMENT; PROGNOSTICS | V5: Context: Predictive maintenance is a technique for creating a more sustainable, safe, and profitable industry. One of the key challenges for creating predictive maintenance systems is the lack of failure data, as the machine is frequently repaired before failure. Digital Twins provide a real-time representation of the physical machine and generate data, such as asset degradation, which the predictive maintenance algorithm can use. Since 2018, scientific literature on the utilization of Digital Twins for predictive maintenance has accelerated, indicating the need for a thorough review. Objective: This research aims to gather and synthesize the studies that focus on predictive maintenance using Digital Twins to pave the way for further research. Method: A systematic literature review (SLR) using an active learning tool is conducted on published primary studies on predictive maintenance using Digital Twins, in which 42 primary studies have been analyzed. Results: This SLR identifies several aspects of predictive maintenance using Digital Twins, including the objectives, application domains, Digital Twin platforms, Digital Twin representation types, approaches, abstraction levels, design patterns, communication protocols, twinning parameters, and challenges and solution directions. These results contribute to a Software Engineering approach for developing predictive maintenance using Digital Twins in academics and the industry. Conclusion: This study is the first SLR in predictive maintenance using Digital Twins. We answer key questions for designing a successful predictive maintenance model leveraging Digital Twins. We found that to this day, computational burden, data variety, and complexity of models, assets, or components are the key challenges in designing these models. | W5: [van Dinter, Raymon] Sioux Technol, Apeldoorn, Netherlands; [van Dinter, Raymon; Tekinerdogan, Bedir] Wageningen Univ & Res, Informat Technol Grp, Wageningen, Netherlands; [Catal, Cagatay] Qatar Univ, Dept Comp Sci & Engn, Doha, Qatar | X5: Wageningen University & Research; Qatar University | Y5: Tekinerdogan, B (corresponding author), Wageningen Univ & Res, Informat Technol Grp, Wageningen, Netherlands. | Z5: bedir.tekinerdogan@wur.nl | AA5: ; Tekinerdogan, Bedir/K-3639-2019; van+Dinter, Raymon/ABD-7476-2021; Catal, Cagatay/AAF-3929-2019 | AB5: Tekinerdogan, Bedir/0000-0002-8538-7261; Dinter, van, Raymon/0000-0002-1811-8803 | AG5: 114 | AH5: 196 | AI5: 232 | AJ5: 52 | AK5: 567 | AL5: ELSEVIER | AM5: AMSTERDAM | AN5: RADARWEG 29, 1043 NX AMSTERDAM, NETHERLANDS | AO5: 0950-5849 | AP5: 1873-6025 | AR5: INFORM SOFTWARE TECH | AS5: Inf. Softw. Technol. | AT5: NOV | AU5: 2022 | AV5: 151 | BD5: 107008 | BE5: 10.1016/j.infsof.2022.107008 | BF5: =HYPERLINK("http://dx.doi.org/10.1016/j.infsof.2022.107008","http://dx.doi.org/10.1016/j.infsof.2022.107008") -> http://dx.doi.org/10.1016/j.infsof.2022.107008 | BH5: JUL 2022 | BI5: 20 | BJ5: Computer Science, Information Systems; Computer Science, Software Engineering | BK5: Science Citation Index Expanded (SCI-EXPANDED) | BL5: Computer Science | BM5: 4V5BX | BO5: Green Accepted, hybrid | BP5: Y | BQ5: N | BR5: 2025-11-04 | BS5: WOS:000859493100007 | BT5: =HYPERLINK("https%3A%2F%2Fwww.webofscience.com%2Fwos%2Fwoscc%2Ffull-record%2FWOS:000859493100007","View Full Record in Web of Science") -> View Full Record in Web of Science
A6: J | B6: Liu, X; Jiang, D; Tao, B; Xiang, F; Jiang, GZ; Sun, Y; Kong, JY; Li, GF | F6: Liu, Xin; Jiang, Du; Tao, Bo; Xiang, Feng; Jiang, Guozhang; Sun, Ying; Kong, Jianyi; Li, Gongfa | I6: A systematic review of digital twin about physical entities, virtual models, twin data, and applications | J6: ADVANCED ENGINEERING INFORMATICS | M6: English | N6: Review | T6: Digital Twin; Physical entity; Virtual model; Twin data; Applications | U6: INDUSTRY 4.0; FRAMEWORK; OPERATIONS; QUALITY; ARCHITECTURE; PROGNOSTICS; PREDICTION; DESIGN; CLOUD | V6: The digital twin is a crucial technology for realizing smart manufacturing and industrial digital transformation, which has received extensive attention and research from industry and academia. After 20 years of development, the application area of digital twins has been pervasive. Due to the diversity of application areas, various reference models and research methods have been presented for the components of the digital twin. Therefore, this paper provides systematic research of current studies on the basic components of the digital twin. This paper analyzed 117 articles from 2017 to 2022. By clarifying the relationship between the digital twin and the cyberphysical system, it first clarified the definition, characteristics, and application areas of the digital twin. On this basis, the research methodology of the core components of the digital twin (physical entities, virtual models, and twin data) is analyzed. At the same time, the application areas of digital twins are analyzed and delineated, and the application potential of the digital twin is explored. Finally, the research results and future research recommendations are presented. | W6: [Liu, Xin; Tao, Bo; Kong, Jianyi; Li, Gongfa] Wuhan Univ Sci & Technol, Key Lab Met Equipment & Control Technol, Minist Educ, Wuhan 430081, Peoples R China; [Liu, Xin; Jiang, Du; Jiang, Guozhang; Kong, Jianyi; Li, Gongfa] Wuhan Univ Sci & Technol, Hubei Key Lab Mech Transmiss & Mfg Engn, Wuhan 430081, Peoples R China; [Jiang, Du; Tao, Bo; Xiang, Feng; Sun, Ying; Li, Gongfa] Wuhan Univ Sci & Technol, Res Ctr Biomimet Robot & Intelligent Measurement &, Wuhan 430081, Peoples R China; [Xiang, Feng; Sun, Ying] Wuhan Univ Sci & Technol, Precis Mfg Res Inst, Wuhan 430081, Peoples R China | X6: Wuhan University of Science & Technology; Wuhan University of Science & Technology; Wuhan University of Science & Technology; Wuhan University of Science & Technology | Y6: Li, GF (corresponding author), Wuhan Univ Sci & Technol, Key Lab Met Equipment & Control Technol, Minist Educ, Wuhan 430081, Peoples R China.;Jiang, D; Li, GF (corresponding author), Wuhan Univ Sci & Technol, Hubei Key Lab Mech Transmiss & Mfg Engn, Wuhan 430081, Peoples R China.;Jiang, D; Li, GF (corresponding author), Wuhan Univ Sci & Technol, Res Ctr Biomimet Robot & Intelligent Measurement &, Wuhan 430081, Peoples R China. | Z6: jiangdu@wust.edu.cn; ligongfa@wust.edu.cn | AA6: Liu, Xin/KYQ-8886-2024; sun, yong/HPD-0054-2023; jiang, guo/OIS-8385-2025; Bo, Tao/AFE-7417-2022 | AB6: Liu, Xin/0000-0001-6028-9692; | AC6: National Natural Science Foundation of China [51975431, 51575407] | AD6: National Natural Science Foundation of China(National Natural Science Foundation of China (NSFC)) | AE6: This research was supported by the National Natural Science Foundation of China (Nos. 51975431, 51575407). | AG6: 150 | AH6: 195 | AI6: 211 | AJ6: 161 | AK6: 1239 | AL6: ELSEVIER SCI LTD | AM6: London | AN6: 125 London Wall, London, ENGLAND | AO6: 1474-0346 | AP6: 1873-5320 | AR6: ADV ENG INFORM | AS6: Adv. Eng. Inform. | AT6: JAN | AU6: 2023 | AV6: 55 | BD6: 101876 | BE6: 10.1016/j.aei.2023.101876 | BF6: =HYPERLINK("http://dx.doi.org/10.1016/j.aei.2023.101876","http://dx.doi.org/10.1016/j.aei.2023.101876") -> http://dx.doi.org/10.1016/j.aei.2023.101876 | BH6: JAN 2023 | BI6: 18 | BJ6: Computer Science, Artificial Intelligence; Engineering, Multidisciplinary | BK6: Science Citation Index Expanded (SCI-EXPANDED) | BL6: Computer Science; Engineering | BM6: M7MU2 | BP6: Y | BQ6: N | BR6: 2025-11-04 | BS6: WOS:001032030200001 | BT6: =HYPERLINK("https%3A%2F%2Fwww.webofscience.com%2Fwos%2Fwoscc%2Ffull-record%2FWOS:001032030200001","View Full Record in Web of Science") -> View Full Record in Web of Science
A7: J | B7: Perno, M; Hvam, L; Haug, A | F7: Perno, Matteo; Hvam, Lars; Haug, Anders | I7: Implementation of digital twins in the process industry: A systematic literature review of enablers and barriers | J7: COMPUTERS IN INDUSTRY | M7: English | N7: Review | T7: Digital twin; Simulation; Process industry; Literature review; Barrier; Enabler | U7: BIG DATA; FUTURE; MODEL; SIMULATION; CHALLENGES; TRANSFORMATION; BLOCKCHAIN; DESIGN; ROLES | V7: Since the introduction of the concept of digital twins (DTs) in 2002, the number of practical applications in different industrial sectors has grown rapidly. Despite the hype surrounding this technology, companies face significant challenges upon deciding to implement DTs in their organizations due to the novelty of the concept. Furthermore, little research on DT has been conducted for the process industry, which may be explained by the high complexity of accurately representing and modeling the physics behind production processes. To consolidate the fragmented literature on the enabling factors and challenges in DT implementation in the process industry, this study organizes the existing studies on DTs with a focus on barriers and enablers. On this basis, this study contributes to the existing body of knowledge on DTs by organizing the DT literature and by proposing conceptual models describing enablers of and barriers to DT implementation, as well as their mutual relationships. (C) 2021 The Author(s). Published by Elsevier B.V. | W7: [Perno, Matteo; Hvam, Lars] Tech Univ Denmark, Dept Technol Management & Econ, Lyngby, Denmark; [Haug, Anders] Univ Southern Denmark, Dept Entrepreneurship & Relationship Management, Kolding, Denmark; [Perno, Matteo] Akademivej,Bldg 358, DK-2800 Lyngby, Denmark | X7: Technical University of Denmark; University of Southern Denmark | Y7: Perno, M (corresponding author), Tech Univ Denmark, Dept Technol Management & Econ, Lyngby, Denmark.;Perno, M (corresponding author), Akademivej,Bldg 358, DK-2800 Lyngby, Denmark. | Z7: matper@dtu.dk; lahv@dtu.dk; adg@sam.sdu.dk | AA7: ; Hvam, Lars/O-4313-2014; Haug, Anders/ABE-2706-2020 | AB7: Perno, Matteo/0000-0003-1165-7510; Haug, Anders/0000-0001-6173-6925 | AC7: Manufacturing Academy of Denmark (MADE); Department of Technology, Management and Economics at the Technical University of Denmark; Haldor Topsoe A/S | AD7: Manufacturing Academy of Denmark (MADE); Department of Technology, Management and Economics at the Technical University of Denmark; Haldor Topsoe A/S | AE7: This research was supported by the Manufacturing Academy of Denmark (MADE), the Department of Technology, Management and Economics at the Technical University of Denmark, and Haldor Topsoe A/S. | AG7: 107 | AH7: 162 | AI7: 183 | AJ7: 7 | AK7: 176 | AL7: ELSEVIER | AM7: AMSTERDAM | AN7: RADARWEG 29, 1043 NX AMSTERDAM, NETHERLANDS | AO7: 0166-3615 | AP7: 1872-6194 | AR7: COMPUT IND | AS7: Comput. Ind. | AT7: JAN | AU7: 2022 | AV7: 134 | BD7: 103558 | BE7: 10.1016/j.compind.2021.103558 | BF7: =HYPERLINK("http://dx.doi.org/10.1016/j.compind.2021.103558","http://dx.doi.org/10.1016/j.compind.2021.103558") -> http://dx.doi.org/10.1016/j.compind.2021.103558 | BI7: 16 | BJ7: Computer Science, Interdisciplinary Applications | BK7: Science Citation Index Expanded (SCI-EXPANDED) | BL7: Computer Science | BM7: 2R1VT | BO7: hybrid | BP7: Y | BQ7: N | BR7: 2025-11-04 | BS7: WOS:000820899900007 | BT7: =HYPERLINK("https%3A%2F%2Fwww.webofscience.com%2Fwos%2Fwoscc%2Ffull-record%2FWOS:000820899900007","View Full Record in Web of Science") -> View Full Record in Web of Science
A8: J | B8: Weil, C; Bibri, SE; Longchamp, R; Golay, F; Alahi, A | F8: Weil, Charlotte; Bibri, Simon Elias; Longchamp, Regis; Golay, Francois; Alahi, Alexandre | I8: Urban Digital Twin Challenges: A Systematic Review and Perspectives for Sustainable Smart Cities | J8: SUSTAINABLE CITIES AND SOCIETY | M8: English | N8: Review | T8: Urban digital twins; Digital twins; Sustainable smart cities; City management; City planning | U8: ARTIFICIAL-INTELLIGENCE; CITY; PLATFORM; IMPLEMENTATION; INTEGRATION; TECHNOLOGY; TOOLS | V8: Recent scientific and technological advancements have transformed the knowledge frontiers, giving rise to the next wave of disruptive technologies with deep impacts on urban society. An Urban Digital Twin (UDT) is a technology with great potential to transform the management and planning of the infrastructures and systems of sustainable smart cities towards environmental sustainability. However, despite the recent increase of research on UDTs due to its widespread diffusion much more recently, there is a lack of studies examining the existing bottlenecks to its implementation. To fill this gap, this study provides a systematic literature review on the key challenges and open issues pertaining to the implementation of an UDT. Results indicate 8 important categories of challenges related to (1) interoperability and semantics; (2) infrastructure, including storage, computation, network; (3) data acquisition and actuation; (4) data quality and harmonization; (5) modeling, simulation and decision-support; (6) data visualization and information display; (7) human and capital resources; and finally (8) governance, organizational and social issues. All topics are significantly raised in the literature, with most emphasis on issues pertaining to data and model semantics, missing data, data quality and modeling. The findings serve to inform practitioners about the bottlenecks delaying the implementation of UDTs. | W8: [Weil, Charlotte; Longchamp, Regis; Golay, Francois] Ecole Polytech Fed Lausanne, Sch Architecture Civil & Environm Engn, ENAC, EPFL, CH-1015 Lausanne, Switzerland; [Bibri, Simon Elias] Ecole Polytech Fed Lausanne, Sch Architecture Civil & Environm Engn, VITA, Visual Intelligence Transportat,ENAC,EPFL, CH-1015 Lausanne, Switzerland; [Alahi, Alexandre] Ecole Polytech fedeale Lausanne, VITA, Visual Intelligence Transportat, EPFL, CH-1015 Lausanne, Switzerland | X8: Swiss Federal Institutes of Technology Domain; Ecole Polytechnique Federale de Lausanne; Swiss Federal Institutes of Technology Domain; Ecole Polytechnique Federale de Lausanne; Swiss Federal Institutes of Technology Domain; Ecole Polytechnique Federale de Lausanne | Y8: Weil, C (corresponding author), Ecole Polytech Fed Lausanne, Sch Architecture Civil & Environm Engn, ENAC, EPFL, CH-1015 Lausanne, Switzerland. | Z8: charlotte.weil@epfl.ch | AA8: Alahi, Alexandre/AAP-5936-2021 | AB8: Golay, Francois/0000-0002-0683-0481; Weil, Charlotte/0000-0002-5423-1440; Bibri, Simon Elias/0009-0003-8559-6885 | AC8: Etat de Geneve, Departement du territoire (DT); European Union; [101034260] | AD8: Etat de Geneve, Departement du territoire (DT); European Union(European Union (EU)); | AE8: This work builds on an analysis conducted for the State of Geneva, mandated and supported financially by Etat de Geneve, Departement du territoire (DT) , Direction de l ' information du territoire through the FUSTIC association, the mandate was coordinated by Dr Frederic Dreyer.This work also received funding from the European Union' s Horizon 2020 research and innovation programme under the Marie Sklodowska-Curie grant agreement No 101034260. | AG8: 142 | AH8: 126 | AI8: 138 | AJ8: 45 | AK8: 167 | AL8: ELSEVIER | AM8: AMSTERDAM | AN8: RADARWEG 29, 1043 NX AMSTERDAM, NETHERLANDS | AO8: 2210-6707 | AP8: 2210-6715 | AR8: SUSTAIN CITIES SOC | AS8: Sust. Cities Soc. | AT8: DEC | AU8: 2023 | AV8: 99 | BD8: 104862 | BE8: 10.1016/j.scs.2023.104862 | BF8: =HYPERLINK("http://dx.doi.org/10.1016/j.scs.2023.104862","http://dx.doi.org/10.1016/j.scs.2023.104862") -> http://dx.doi.org/10.1016/j.scs.2023.104862 | BH8: AUG 2023 | BI8: 15 | BJ8: Construction & Building Technology; Green & Sustainable Science & Technology; Energy & Fuels | BK8: Science Citation Index Expanded (SCI-EXPANDED) | BL8: Construction & Building Technology; Science & Technology - Other Topics; Energy & Fuels | BM8: S2NG9 | BO8: Green Submitted | BP8: Y | BQ8: N | BR8: 2025-11-04 | BS8: WOS:001069583500001 | BT8: =HYPERLINK("https%3A%2F%2Fwww.webofscience.com%2Fwos%2Fwoscc%2Ffull-record%2FWOS:001069583500001","View Full Record in Web of Science") -> View Full Record in Web of Science
A9: J | B9: Lei, BY; Janssen, P; Stoter, J; Biljecki, F | F9: Lei, Binyu; Janssen, Patrick; Stoter, Jantien; Biljecki, Filip | I9: Challenges of urban digital twins: A systematic review and a Delphi expert survey | J9: AUTOMATION IN CONSTRUCTION | M9: English | N9: Review | T9: 3D city model; City information model; Virtual replica; Simulations; Urban planning | U9: FRAMEWORK; FUTURE; DESIGN; REFLECTIONS; LESSONS; CITIES; STATE; ART | V9: Many challenges to operate digital twins remain, hindering their design and implementation, and are rarely discussed. Furthermore, issues of social and legal nature are often overlooked. We identify the challenges of operating digital twins in the urban context through a bifurcated and multi-dimensional approach: a systematic literature review and an expert survey. The review organises the identified challenges across technical and non-technical dimensions. As the topic is novel, the corpus is rather small and lacking the contextualisation of challenges. Thus, we complement it with a survey based on the Delphi method, involving a diverse panel of domain experts covering academia, industry and government organisations. Combining the results, we identify 14 technical and 9 non-technical challenges and map them to phases of the digital twin's life cycle. The most severe challenges appear to be related to interoperability (e.g. disparate semantic standards) and practical value (e.g. lack of business models). | W9: [Lei, Binyu; Janssen, Patrick; Biljecki, Filip] Natl Univ Singapore, Dept Architecture, Singapore, Singapore; [Stoter, Jantien] Delft Univ Technol, 3D Geoinformat Grp, Delft, Netherlands; [Biljecki, Filip] Natl Univ Singapore, Dept Real Estate, Singapore, Singapore; [Biljecki, Filip] Natl Univ Singapore, Dept Architecture, 4 Architecture Dr, Singapore 117566, Singapore | X9: National University of Singapore; Delft University of Technology; National University of Singapore; National University of Singapore | Y9: Biljecki, F (corresponding author), Natl Univ Singapore, Dept Architecture, 4 Architecture Dr, Singapore 117566, Singapore. | Z9: filip@nus.edu.sg | AA9: Lei, Binyu/JMC-2680-2023; Biljecki, Filip/B-9829-2013; Janssen, Patrick/J-6019-2015 | AB9: Lei, Binyu/0000-0002-8501-3104; Stoter, Jantien/0000-0002-1393-7279 | AC9: National University of Singapore; Singapore Ministry of Education Academic Research Fund Tier 1; [R-295-000-171-133] | AD9: National University of Singapore(National University of Singapore); Singapore Ministry of Education Academic Research Fund Tier 1(Ministry of Education, Singapore); | AE9: The Institutional Review Board of the National University of Singa-pore has reviewed and approved the ethical aspects of this research (Reference Code: NUS-IRB-2022-87) . We are grateful to all expert panellists for their time and patience to participate in our Delphi survey and providing valuable responses for this research. We particularly wish to thank the European Spatial Data Research network (EuroSDR) and the 3D Information Management (3DIM) Domain Working Group of the Open Geospatial Consortium (OGC) for their kind efforts to distribute our survey. We thank Dr Claire Ellul (University College London) for her support and discussions related to the survey. We thank the members of the NUS Urban Analytics Lab for the discussions, in particular, Dr Pengyuan Liu for the constructive comments on the earlyversions of the paper. This research is part of the projects (i) Large-scale 3D Geospatial Data for Urban Analytics, which is supported by the National University of Singapore under the Start Up Grant R-295-000-171-133; and (ii) Multi-scale Digital Twins for the Urban Environment: From Heartbeats to Cities, which is supported by the Singapore Ministry of Education Academic Research Fund Tier 1. | AG9: 125 | AH9: 101 | AI9: 107 | AJ9: 25 | AK9: 201 | AL9: ELSEVIER | AM9: AMSTERDAM | AN9: RADARWEG 29, 1043 NX AMSTERDAM, NETHERLANDS | AO9: 0926-5805 | AP9: 1872-7891 | AR9: AUTOMAT CONSTR | AS9: Autom. Constr. | AT9: MAR | AU9: 2023 | AV9: 147 | BD9: 104716 | BE9: 10.1016/j.autcon.2022.104716 | BF9: =HYPERLINK("http://dx.doi.org/10.1016/j.autcon.2022.104716","http://dx.doi.org/10.1016/j.autcon.2022.104716") -> http://dx.doi.org/10.1016/j.autcon.2022.104716 | BH9: JAN 2023 | BI9: 15 | BJ9: Construction & Building Technology; Engineering, Civil | BK9: Science Citation Index Expanded (SCI-EXPANDED) | BL9: Construction & Building Technology; Engineering | BM9: 8I1UV | BO9: hybrid | BP9: Y | BQ9: N | BR9: 2025-11-04 | BS9: WOS:000921513800001 | BT9: =HYPERLINK("https%3A%2F%2Fwww.webofscience.com%2Fwos%2Fwoscc%2Ffull-record%2FWOS:000921513800001","View Full Record in Web of Science") -> View Full Record in Web of Science
A10: J | B10: Bibri, SE; Huang, J; Jagatheesaperumal, SK; Krogstie, J | F10: Bibri, Simon Elias; Huang, Jeffrey; Jagatheesaperumal, Senthil Kumar; Krogstie, John | I10: The synergistic interplay of artificial intelligence and digital twin in environmentally planning sustainable smart cities: A comprehensive systematic review | J10: ENVIRONMENTAL SCIENCE AND ECOTECHNOLOGY | M10: English | N10: Review | T10: Sustainable smart cities; Arti ficial intelligence; Arti ficial intelligence of things; Urban digital twin; Data -driven urban planning; Environmental planning; Environmental sustainability | U10: OF-THE-ART; BIG DATA; CHALLENGES; PLATFORM; THINGS; TOOLS; OPPORTUNITIES; COMPLEXITY; METAVERSE; INTERNET | V10: The dynamic landscape of sustainable smart cities is witnessing a signi ficant transformation due to the integration of emerging computational technologies and innovative models. These advancements are reshaping data -driven planning strategies, practices, and approaches, thereby facilitating the achievement of environmental sustainability goals. This transformative wave signals a fundamental shift d marked by the synergistic operation of arti ficial intelligence (AI), arti ficial intelligence of things (AIoT), and urban digital twin (UDT) technologies. While previous research has largely explored urban AI, urban AIoT, and UDT in isolation, a signi ficant knowledge gap exists regarding their synergistic interplay, collaborative integration, and collective impact on data -driven environmental planning in the dynamic context of sustainable smart cities. To address this gap, this study conducts a comprehensive systematic review to uncover the intricate interactions among these interconnected technologies, models, and domains while elucidating the nuanced dynamics and untapped synergies in the complex ecosystem of sustainable smart cities. Central to this study are four guiding research questions: 1. What theoretical and practical foundations underpin the convergence of AI, AIoT, UDT, data -driven planning, and environmental sustainability in sustainable smart cities, and how can these components be synthesized into a novel comprehensive framework? 2. How does integrating AI and AIoT reshape the landscape of datadriven planning to improve the environmental performance of sustainable smart cities? 3. How can AI and AIoT augment the capabilities of UDT to enhance data -driven environmental planning processes in sustainable smart cities? 4. What challenges and barriers arise in integrating and implementing AI, AIoT, and UDT in data -driven environmental urban planning, and what strategies can be devised to surmount or mitigate them? Methodologically, this study involves a rigorous analysis and synthesis of studies published between January 2019 and December 2023, comprising an extensive body of literature totaling 185 studies. The findings of this study surpass mere interdisciplinary theoretical enrichment, offering valuable insights into the transformative potential of integrating AI, AIoT, and UDT technologies to advance sustainable urban development practices. By enhancing data -driven environmental planning processes, these integrated technologies and models offer innovative solutions to address complex environmental challenges. However, this endeavor is fraught with formidable challenges and complexities that require careful navigation and mitigation to achieve desired outcomes. This study serves as a comprehensive reference guide, spurring groundbreaking research endeavors, stimulating practical implementations, informing strategic initiatives, and shaping policy formulations in sustainable urban development. These insights have profound implications for researchers, practitioners, and policymakers, providing a roadmap for fostering resiliently designed, technologically advanced, and environmentally conscious urban environments. (c) 2024 The Author(s). Published by Elsevier B.V. on behalf of Chinese Society for Environmental Sciences, Harbin Institute of Technology, Chinese Research Academy of Environmental Sciences. This is an open access article under the CC BY license (http://creativecommons.org/licenses/by/4.0/). | W10: [Bibri, Simon Elias; Huang, Jeffrey] Swiss Fed Inst Technol Lausanne EPFL, Inst Comp & Commun Sci IINFCOM, Sch Architecture Civil & Environm Engn ENAC, Media & Design Lab LDM, CH-1015 Lausanne, Switzerland; [Jagatheesaperumal, Senthil Kumar] Mepco Schlenk Engn Coll, Dept Elect & Commun Engn, Sivakasi 626005, Tamilnadu, India; [Krogstie, John] Norwegian Univ Sci & Technol NTNU, Dept Comp Sci, Trondheim, Norway | X10: Swiss Federal Institutes of Technology Domain; Ecole Polytechnique Federale de Lausanne; Mepco Schlenk Engineering College; Norwegian University of Science & Technology (NTNU) | Y10: Bibri, SE (corresponding author), Swiss Fed Inst Technol Lausanne EPFL, Inst Comp & Commun Sci IINFCOM, Sch Architecture Civil & Environm Engn ENAC, Media & Design Lab LDM, CH-1015 Lausanne, Switzerland. | Z10: simon.bibri@epfl.ch | AA10: Jagatheesaperumal, Senthil Kumar/S-9258-2019; Jagatheesaperumal, Senthil Kumar/S-9258-2019; Krogstie, John/NBX-4350-2025 | AB10: Jagatheesaperumal, Senthil Kumar/0000-0002-9516-0327; Jagatheesaperumal, Senthil Kumar/0000-0002-9516-0327; Krogstie, John/0000-0003-4830-1876 | AG10: 208 | AH10: 68 | AI10: 78 | AJ10: 49 | AK10: 137 | AL10: ELSEVIER | AM10: AMSTERDAM | AN10: RADARWEG 29, 1043 NX AMSTERDAM, NETHERLANDS | AO10: 2666-4984 | AR10: ENVIRON SCI ECOTECH | AS10: Env. Sci. Ecotechnol. | AT10: JUL | AU10: 2024 | AV10: 20 | BD10: 100433 | BE10: 10.1016/j.ese.2024.100433 | BF10: =HYPERLINK("http://dx.doi.org/10.1016/j.ese.2024.100433","http://dx.doi.org/10.1016/j.ese.2024.100433") -> http://dx.doi.org/10.1016/j.ese.2024.100433 | BH10: MAY 2024 | BI10: 26 | BJ10: Green & Sustainable Science & Technology; Environmental Sciences | BK10: Science Citation Index Expanded (SCI-EXPANDED) | BL10: Science & Technology - Other Topics; Environmental Sciences & Ecology | BM10: UA0B0 | BN10: 38831974 | BO10: Green Submitted, gold | BP10: Y | BQ10: N | BR10: 2025-11-04 | BS10: WOS:001245213400001 | BT10: =HYPERLINK("https%3A%2F%2Fwww.webofscience.com%2Fwos%2Fwoscc%2Ffull-record%2FWOS:001245213400001","View Full Record in Web of Science") -> View Full Record in Web of Science

Sheet 1_20251104.wos.table
A1: ID | B1: DOI | C1: Title | D1: Databases
A2: DT.DBQ1.01 | B2: ='1_20251104.wos'!BF2 -> http://dx.doi.org/10.1016/j.cirpj.2020.02.002 | C2: ='1_20251104.wos'!I2 -> Characterising the Digital Twin: A systematic literature review
A3: DT.DBQ1.02 | B3: ='1_20251104.wos'!BF3 -> http://dx.doi.org/10.1016/j.compind.2021.103469 | C3: ='1_20251104.wos'!I3 -> Digital twin paradigm: A systematic literature review
A4: DT.DBQ1.03 | B4: ='1_20251104.wos'!BF4 -> http://dx.doi.org/10.1109/ACCESS.2021.3060863 | C4: ='1_20251104.wos'!I4 -> The Role of AI, Machine Learning, and Big Data in Digital Twinning: A Systematic Literature Review, Challenges, and Opportunities
A5: DT.DBQ1.04 | B5: ='1_20251104.wos'!BF5 -> http://dx.doi.org/10.1016/j.infsof.2022.107008 | C5: ='1_20251104.wos'!I5 -> Predictive maintenance using digital twins: A systematic literature review
A6: DT.DBQ1.05 | B6: ='1_20251104.wos'!BF6 -> http://dx.doi.org/10.1016/j.aei.2023.101876 | C6: ='1_20251104.wos'!I6 -> A systematic review of digital twin about physical entities, virtual models, twin data, and applications
A7: DT.DBQ1.06 | B7: ='1_20251104.wos'!BF7 -> http://dx.doi.org/10.1016/j.compind.2021.103558 | C7: ='1_20251104.wos'!I7 -> Implementation of digital twins in the process industry: A systematic literature review of enablers and barriers
A8: DT.DBQ1.07 | B8: ='1_20251104.wos'!BF8 -> http://dx.doi.org/10.1016/j.scs.2023.104862 | C8: ='1_20251104.wos'!I8 -> Urban Digital Twin Challenges: A Systematic Review and Perspectives for Sustainable Smart Cities
A9: DT.DBQ1.08 | B9: ='1_20251104.wos'!BF9 -> http://dx.doi.org/10.1016/j.autcon.2022.104716 | C9: ='1_20251104.wos'!I9 -> Challenges of urban digital twins: A systematic review and a Delphi expert survey
A10: DT.DBQ1.09 | B10: ='1_20251104.wos'!BF10 -> http://dx.doi.org/10.1016/j.ese.2024.100433 | C10: ='1_20251104.wos'!I10 -> The synergistic interplay of artificial intelligence and digital twin in environmentally planning sustainable smart cities: A comprehensive systematic review
C11: ='1_20251104.wos'!I11

Sheet 1_20251104.wos_results
A1: Database | B1: Num | C1: ='1_20251104.wos.table'!A2 -> DT.DBQ1.01 | D1: ='1_20251104.wos.table'!A3 -> DT.DBQ1.02 | E1: ='1_20251104.wos.table'!A4 -> DT.DBQ1.03 | F1: ='1_20251104.wos.table'!A5 -> DT.DBQ1.04 | G1: ='1_20251104.wos.table'!A6 -> DT.DBQ1.05 | H1: ='1_20251104.wos.table'!A7 -> DT.DBQ1.06 | I1: ='1_20251104.wos.table'!A8 -> DT.DBQ1.07 | J1: ='1_20251104.wos.table'!A9 -> DT.DBQ1.08 | K1: ='1_20251104.wos.table'!A10 -> DT.DBQ1.09 | L1: Total | M1: Percentual | N1: Percentual cumulativo | O1: Percentual
A2: Scopus | B2: 1 | D2: 1 | E2: 1 | F2: 1 | G2: 1 | H2: 1 | I2: 1 | K2: 1 | L2: =SUM(C2:K2) -> 7 | M2: =L2/$L$18 -> 0.18421053 | N2: =M2 -> 0.18421053 | O2: =1/B17 -> 0.0625
A3: ScienceDirect | B3: =B2+1 -> 2 | D3: 1 | E3: 1 | F3: 1 | I3: 1 | K3: 1 | L3: =SUM(C3:K3) -> 5 | M3: =L3/$L$18 -> 0.13157895 | N3: =N2+M3 -> 0.31578947 | O3: =O2+1/$B$17 -> 0.125
A4: IEEE Xplore (IEEE, IET) | B4: =B3+1 -> 3 | E4: 1 | F4: 1 | G4: 1 | H4: 1 | L4: =SUM(C4:K4) -> 4 | M4: =L4/$L$18 -> 0.10526316 | N4: =N3+M4 -> 0.42105263 | O4: =O3+1/$B$17 -> 0.1875
A5: ACM digital library | B5: =B4+1 -> 4 | E5: 1 | F5: 1 | H5: 1 | L5: =SUM(C5:K5) -> 3 | M5: =L5/$L$18 -> 0.078947368 | N5: =N4+M5 -> 0.5 | O5: =O4+1/$B$17 -> 0.25
A6: Wiley online library | B6: =B5+1 -> 5 | E6: 1 | F6: 1 | G6: 1 | L6: =SUM(C6:K6) -> 3 | M6: =L6/$L$18 -> 0.078947368 | N6: =N5+M6 -> 0.57894737 | O6: =O5+1/$B$17 -> 0.3125
A7: Web of Science | B7: =B6+1 -> 6 | H7: 1 | I7: 1 | K7: 1 | L7: =SUM(C7:K7) -> 3 | M7: =L7/$L$18 -> 0.078947368 | N7: =N6+M7 -> 0.65789474 | O7: =O6+1/$B$17 -> 0.375
A8: SpringerLink (Springer) | B8: =B7+1 -> 7 | E8: 1 | F8: 1 | L8: =SUM(C8:K8) -> 2 | M8: =L8/$L$18 -> 0.052631579 | N8: =N7+M8 -> 0.71052632 | O8: =O7+1/$B$17 -> 0.4375
A9: Taylor & Francis online | B9: =B8+1 -> 8 | E9: 1 | F9: 1 | L9: =SUM(C9:K9) -> 2 | M9: =L9/$L$18 -> 0.052631579 | N9: =N8+M9 -> 0.76315789 | O9: =O8+1/$B$17 -> 0.5
A10: Google Scholar | B10: =B9+1 -> 9 | G10: 1 | I10: 1 | L10: =SUM(C10:K10) -> 2 | M10: =L10/$L$18 -> 0.052631579 | N10: =N9+M10 -> 0.81578947 | O10: =O9+1/$B$17 -> 0.5625
A11: CIRP | B11: =B10+1 -> 10 | C11: 1 | L11: =SUM(C11:K11) -> 1 | M11: =L11/$L$18 -> 0.026315789 | N11: =N10+M11 -> 0.84210526 | O11: =O10+1/$B$17 -> 0.625
A12: IFAC-Papers Online 7 | B12: =B11+1 -> 11 | C12: 1 | L12: =SUM(C12:K12) -> 1 | M12: =L12/$L$18 -> 0.026315789 | N12: =N11+M12 -> 0.86842105 | O12: =O11+1/$B$17 -> 0.6875
A13: Procedia Manufacturing | B13: =B12+1 -> 12 | C13: 1 | L13: =SUM(C13:K13) -> 1 | M13: =L13/$L$18 -> 0.026315789 | N13: =N12+M13 -> 0.89473684 | O13: =O12+1/$B$17 -> 0.75
A14: International Journal of Advanced Manufacturing Technology | B14: =B13+1 -> 13 | C14: 1 | L14: =SUM(C14:K14) -> 1 | M14: =L14/$L$18 -> 0.026315789 | N14: =N13+M14 -> 0.92105263 | O14: =O13+1/$B$17 -> 0.8125
A15: Journal of Ambient Intelligence and Humanoid Computing | B15: =B14+1 -> 14 | C15: 1 | L15: =SUM(C15:K15) -> 1 | M15: =L15/$L$18 -> 0.026315789 | N15: =N14+M15 -> 0.94736842 | O15: =O14+1/$B$17 -> 0.875
A16: Hindawi | B16: =B15+1 -> 15 | E16: 1 | L16: =SUM(C16:K16) -> 1 | M16: =L16/$L$18 -> 0.026315789 | N16: =N15+M16 -> 0.97368421 | O16: =O15+1/$B$17 -> 0.9375
A17: IGI-Global | B17: =B16+1 -> 16 | E17: 1 | L17: =SUM(C17:K17) -> 1 | M17: =L17/$L$18 -> 0.026315789 | N17: =N16+M17 -> 1 | O17: =O16+1/$B$17 -> 1
A18: Total | C18: =SUM(C2:C17) -> 5 | D18: =SUM(D2:D17) -> 2 | E18: =SUM(E2:E17) -> 9 | F18: =SUM(F2:F17) -> 7 | G18: =SUM(G2:G17) -> 4 | H18: =SUM(H2:H17) -> 4 | I18: =SUM(I2:I17) -> 4 | J18: =SUM(J2:J17) -> 0 | ... M18: =SUM(M2:M17) -> 1

Sheet scopus_export_Nov 16-2025_filte
A1: Key | B1: Item Type | C1: Publication Year | D1: Author | E1: Title | F1: Publication Title | G1: ISBN | H1: ISSN | I1: DOI | J1: Url | K1: Abstract Note | L1: Date | M1: Date Added | N1: Date Modified | O1: Access Date | P1: Pages | Q1: Num Pages | R1: Issue | S1: Volume | T1: Number Of Volumes | U1: Journal Abbreviation | V1: Short Title | W1: Series | X1: Series Number | Y1: Series Text | Z1: Series Title | AA1: Publisher | AB1: Place | AC1: Language | AD1: Rights | AE1: Type | AF1: Archive | AG1: Archive Location | AH1: Library Catalog | AI1: Call Number | AJ1: Extra | AK1: Notes | AL1: File Attachments | AM1: Link Attachments | AN1: Manual Tags | AO1: Automatic Tags | AP1: Editor | AQ1: Series Editor | AR1: Translator | AS1: Contributor | AT1: Attorney Agent | AU1: Book Author | AV1: Cast Member | AW1: Commenter | AX1: Composer | AY1: Cosponsor | AZ1: Counsel | BA1: Interviewer | BB1: Producer | BC1: Recipient | BD1: Reviewed Author | BE1: Scriptwriter | BF1: Words By | BG1: Guest | BH1: Number | BI1: Edition | BJ1: Running Time | BK1: Scale | BL1: Medium | BM1: Artwork Size | BN1: Filing Date | BO1: Application Number | BP1: Assignee | BQ1: Issuing Authority | BR1: Country | BS1: Meeting Name | BT1: Conference Name | BU1: Court | BV1: References | BW1: Reporter | BX1: Legal Status | BY1: Priority Numbers | BZ1: Programming Language | CA1: Version | CB1: System | CC1: Code | CD1: Code Number | CE1: Section | CF1: Session | CG1: Committee | CH1: History | CI1: Legislative Body
A2: Y3PA3JS8 | B2: journalArticle | C2: 2024 | D2: Aghazadeh Ardebili, A.; Zappatore, M.; Ramadan, A.I.H.A.; Longo, A.; Ficarella, A. | E2: Digital Twins of smart energy systems: a systematic literature review on enablers, design, management and computational challenges | F2: Energy Informatics | H2: 25208942 (ISSN) | I2: 10.1186/s42162-024-00385-5 | J2: https://www.scopus.com/inward/record.uri?eid=2-s2.0-85205923870&doi=10.1186%2Fs42162-024-00385-5&partnerID=40&md5=806c3f02ba8c9f382702f93b30376aed | K2: Background: Energy systems, as critical infrastructures (CI), constitute Cyber-Physical-Social Systems (CPSS). Due to their inherent complexity and the importance of service continuity of CIs, digitization in this context encounters significant practical challenges. Digital Twins (DT) have emerged over the recent years as a promising solution for managing CPSSs by facilitating real-time interaction, synchronization, and control of physical assets. The selection of an appropriate architectural framework is crucial in constructing a DT, to ensure integration of enabling technologies and data from diverse sources. Objectives: This study proposes a Systematic Literature Review (SLR) to examine technological enablers, design choices, management strategies and Computational Challenges of DTs in Smart Energy Systems (SES) by also analyzing existing architectures and identifying key components. Methods: The SLR follows a rigorous workflow exploiting a multi-database search with predefined eligibility criteria, accompanied by advanced searching techniques, such as manual screening of results and a documented search strategy, in order to ensure its comprehensiveness and reliability, More specifically, research questions are first defined and then submitted as queries to scientific digital libraries (i.e., IEEE Xplore, Scopus, and WoS) selected due to their coverage and reliability (Google Scholar was excluded for the presence of grey literature and non-peer-reviewed material). Then, inclusion and exclusion criteria are established to filter the results and shortlist the significant publications. Subsequently, relevant data are extracted, summarized, and categorized in order to identify common themes, existing gaps, and future research directions, with the aim of providing a comprehensive overview of the current state of DTs for SESs. Results: From the proposed DT-based solutions described in the selected publications, the adopted architectures are examined and categorized depending on their logical building blocks, microservices, enabling technologies, human–machine interfaces (HMI), artificial intelligence and machine learning (AI/ML) implementations, data flow and data persistence choices, and Internet-of-Things (IoT) components involved. Additionally, the integration of edge-cloud computing and IoT technologies in literature are studied and discussed. Finally, gaps, opportunities, future study lines, and challenges of implementing DTs are thoroughly addressed. The results achieved also pave the way for a forthcoming design pattern catalog for DTs in CPSSs capable of supporting the engineering and research communities, by offering practical insights on implementation and integration aspects. Conclusion: The proposed SLR provides a valuable resource for designing and implementing DTs of CPSSs in general and of SESs in particular. Furthermore, it highlights the potential benefits of adopting DTs to manage complex energy systems and it identifies areas for future research. © 2024 Elsevier B.V., All rights reserved. | L2: 2024 | M2: 45977.672 | N2: 45981.516 | R2: 1 | S2: 7 | U2: Energy. Inform. | AC2: English | AF2: Scopus | AJ2: Publisher: Springer Nature | AN2: Reviews; Network security; Digital Twin; Bibliographies; Systems architecture; Cyber-physical systems; Interoperability; Energy; Cybe-physical systems; Complex system; Cybe-physical-social system; Cyber physicals; Cyber-Physical System; Cyber-Physical-Social System; Edge clouds; Edge-cloud continuum; Edge-Cloud Continuum; Empowerment of personnel; Energy internet; Energy internet-of-thing; Energy IoT; Failure rate; Fault tree analysis; Foil bearings; Gas bearings; Graph structures; Internet of energy; Magnetic couplings; Piston rings; Railroad bearings; Ring springs; Rotating disks; Screws; SGML; Shear walls; Smart energy system; Smart energy systems; Social systems; System architecture; Variable speed drives; Voltage scaling; included
A3: JMC9E8SA | B3: journalArticle | C3: 2025 | D3: Antonesi, G.; Cioara, T.; Anghel, I.; Michalakopoulos, V.; Sarmas, E.; Toderean, L. | E3: A systematic review of transformers and large language models in the energy sector: towards agentic digital twins | F3: Applied Energy | H3: 18729118 (ISSN); 03062619 (ISSN) | I3: 10.1016/j.apenergy.2025.126670 | J3: https://www.scopus.com/inward/record.uri?eid=2-s2.0-105013772709&doi=10.1016%2Fj.apenergy.2025.126670&partnerID=40&md5=c1cad25a7dc752b2dbd6cb8ee9706b33 | K3: Artificial intelligence (AI) has long promised to improve energy management in smart grids by enhancing situational awareness and supporting more effective decision-making. While traditional machine learning has demonstrated notable results in forecasting and optimization, it often struggles with generalization, situational awareness, and heterogeneous data integration. Recent advances in Transformer architecture, including Large Language Models (LLMs) and Foundation Models (FMs) can significantly improve the ability to model complex temporal and contextual relationships, as well as in multi-modal data fusion which is valuable for most AI applications in the energy sector. In this review, we synthesize the rapidly expanding field of AI applications in the energy domain, with a focus on Transformer Models (TMs) and LLMs, which have shown growing relevance. We examine the architectural foundations, domain-specific adaptations and practical implementations of TMs across various forecasting and grid management tasks. We then explore the emerging role of LLMs in the field: adaptation and fine tuning for the energy sector, the type of tasks they are suited for, and the new challenges they introduce. Along the way, we highlight practical implementations, innovations, and areas where the research frontier is rapidly expanding. These recent developments reviewed underscore a broader trend: Generative AI (GenAI) is beginning to augment decision-making not only in high-level planning but also in day-to-day operations, from forecasting and grid balancing to workforce training and asset onboarding. While FMs hold promises, we found limited evidence of their concrete application in energy domain to date. Therefore we introduce the concept of the Agentic Digital Twin, a next-generation model that integrates FMs to bring multi-modal situational awareness, autonomy, proactivity, and social interaction into digital twin-based energy management systems. We present the transformational impact of FMs to each phase of a digital twin and identify the open challenges that need to be addressed for their efficient and effective integration. © 2025 Elsevier B.V., All rights reserved. | L3: 2025 | M3: 45977.672 | N3: 45981.512 | S3: 401 | U3: Appl. Energy | AC3: English | AF3: Scopus | AJ3: Publisher: Elsevier Ltd | AN3: Artificial intelligence; machine learning; literature review; Large language models; Data integration; Digital twin; Agentic digital twins; Energy sector; Foundation models; GenAI; Generative AI; Smart grid; Transformers; Forecasting; Decision making; Agentic digital twin; Behavioral research; digitization; Electric transformers; energy management; Energy policy; Generative artificial intelligence; Language model; Large language model; Modal analysis; numerical model; Situational awareness; smart grid; Smart power grids; Transformer; included
A4: URBJYMAX | B4: conferencePaper | C4: 2023 | D4: Arin, I.A.; Meyliana, n.; Warnars, H.L.H.S.; Murad, D.F. | E4: A Systematic Literature Review of Recent Trends and Challenges in Digital Twin Implementation | F4: Int. Conf. ICT for Smart Soc., ICISS - Proceeding | G4: 9798350339543 (ISBN) | I4: 10.1109/ICISS59129.2023.10291219 | J4: https://www.scopus.com/inward/record.uri?eid=2-s2.0-85177460118&doi=10.1109%2FICISS59129.2023.10291219&partnerID=40&md5=a6bc6d3e07f2b2bddf90df9ceb1c59fd | K4: This paper reviews the latest trends and challenges in implementing digital twin technology. A digital twin is a tool used in various industries to improve efficiency, optimize processes, and enable advanced analysis. The review involved searching major research databases and search engines for articles published between 2018 and 2023. The findings reveal several important trends, including the development of different types of digital twin dimensions, each with its own advantages and limitations. The benefits of digital twin implementation include improved decision-making, increased productivity, and operational efficiency. However, there are challenges, such as data integration, security and privacy concerns, a lack of standardization, and the need for experts to effectively design and operate digital twins. The implications of these trends and challenges are discussed regarding their impact on the successful adoption and implementation of digital twin technology. The review also highlights the need to address these challenges and explore new approaches for maximizing the benefits of digital twin technology. Overall, this comprehensive review is a valuable resource for researchers, practitioners, and organizations seeking to understand the current landscape, identify areas for improvement, and make informed decisions when implementing digital twin technology. © 2023 Elsevier B.V., All rights reserved. | L4: 2023 | M4: 45977.672 | N4: 45981.511 | AA4: Institute of Electrical and Electronics Engineers Inc. | AC4: English | AF4: Scopus | AJ4: Journal Abbreviation: Int. Conf. ICT for Smart Soc., ICISS - Proceeding | AN4: digital twin; Systematic literature review; Data integration; systematic literature review; Decision making; Decisions makings; Challenge; Search engines; Efficiency; challenges; Advanced analysis; implementation; Implementation; Increased productivity; Operational efficiencies; Recent trends; Research database; Trend; trends; included
